Workbook
Name Excel_BuiltIn__FilterDatabase: box2metadata!$A$1:$P$109

Sheet tab
A1: ENTITY | B1: SHORTNAME | C1: LABEL | D1: PRIORITY | E1: LEADING | F1: SECURITY
A2: Person | B2: details | C2: Profile | D2: 0 | E2: y | F2: PUBLIC
A3: Person | B3: creators | C3: creator of | D3: 2 | E3: n | F3: PUBLIC
A4: Person | B4: contributors | C4: contributor of | D4: 4 | E4: n | F4: PUBLIC
A5: Person | B5: fonds | C5: Fonds | D5: 6 | E5: n | F5: PUBLIC
A6: Person | B6: personeditors | C6: Person Editors | D6: 8 | E6: n | F6: PUBLIC
A7: Person | B7: personexternallinks | C7: External Links | D7: 10 | E7: n | F7: PUBLIC
A8: OrgUnit | B8: maininformation | C8: Information | D8: 0 | E8: y | F8: PUBLIC
A9: OrgUnit | B9: publications | C9: Publications | D9: 2 | E9: n | F9: PUBLIC
A10: OrgUnit | B10: projects | C10: Projects | D10: 4 | E10: n | F10: PUBLIC
A11: OrgUnit | B11: people | C11: People | D11: 6 | E11: n | F11: PUBLIC
A12: OrgUnit | B12: organizationeditors | C12: Organization Editors | D12: 8 | E12: n | F12: PUBLIC
... A36: Journal_Issue | B36: details | C36: Details | D36: 0 | E36: y | F36: PUBLIC

Sheet tab2box
A1: ENTITY | B1: TAB | C1: ROW | D1: ROW_STYLE | E1: CELL_STYLE | F1: BOXES
A2: OrgUnit | B2: maininformation | C2: 1 | F2: details
A3: OrgUnit | B3: maininformation | C3: 2 | F3: description
A4: OrgUnit | B4: maininformation | C4: 3 | F4: SubOrgUnits
A5: OrgUnit | B5: publications | C5: 1 | F5: publications
A6: OrgUnit | B6: projects | C6: 1 | F6: projects
A7: OrgUnit | B7: people | C7: 1 | F7: people
A8: OrgUnit | B8: organizationeditors | C8: 1 | F8: organizationeditors
A9: Project | B9: maininformation | C9: 1 | F9: primarydata
A10: Project | B10: maininformation | C10: 2 | F10: description
A11: Project | B11: maininformation | C11: 3 | F11: publications
A12: Person | B12: details | C12: 1 | F12: profile
A13: Person | B13: creators | C13: 1 | F13: publications
... A50: Journal_Issue | B50: details | C50: 1 | F50: details

Sheet box
A1: ENTITY | B1: COLLAPSED | C1: TYPE | D1: SHORTNAME | E1: LABEL | F1: CONTAINER | G1: MINOR | H1: SECURITY | I1: STYLE
A2: Person | B2: n | D2: heading | F2: n | G2: n | H2: PUBLIC
A3: Person | B3: n | C3: RELATION | D3: projects | E3: Projects | F3: n | G3: n | H3: PUBLIC
A4: Person | B4: n | C4: RELATION | D4: researchoutputs | E4: Publications | F4: n | G4: n | H4: PUBLIC
A5: Person | B5: n | D5: qualifications | E5: Professional Qualifications | F5: n | G5: n | H5: PUBLIC
A6: Person | B6: n | D6: media | E6: Media Contact Directory | F6: n | G6: n | H6: PUBLIC
A7: Person | B7: n | C7: ORCID_SYNC_QUEUE | D7: orcidsyncqueue | E7: ORCID Registry Queue | F7: n | G7: n | H7: OWNER ONLY
A8: Person | B8: n | D8: namecard | E8: Name Card | F8: n | G8: y | H8: PUBLIC
A9: Person | B9: n | C9: ORCID_SYNC_SETTINGS | D9: orcidsyncsettings | E9: ORCID Synchronization settings | F9: n | G9: n | H9: OWNER ONLY
A10: Person | B10: n | D10: researcherprofile | E10: Profile | F10: n | G10: n | H10: PUBLIC
A11: Person | B11: n | C11: ORCID_AUTHORIZATIONS | D11: orcidauthorizations | E11: ORCID Authorizations | F11: n | G11: n | H11: OWNER ONLY
A12: Person | B12: n | C12: METRICS | D12: metrics | E12: Metrics | F12: n | G12: n | H12: PUBLIC
A13: Person | B13: n | C13: METRICS | D13: usagemetrics | E13: Usage Metrics | F13: n | G13: n | H13: PUBLIC
A14: Person | B14: n | D14: secure | E14: Secured box | F14: n | G14: y | H14: CUSTOM DATA
A15: Person | B15: n | C15: HIERARCHY | D15: affiliation | E15: Affiliation | F15: n | G15: n | H15: PUBLIC
A16: OrgUnit | B16: n | C16: RELATION | D16: rpprojects | E16: OrgUnit's Researchers projects | F16: n | G16: n | H16: PUBLIC
A17: OrgUnit | B17: n | C17: RELATION | D17: publications | E17: OrgUnit's Publications | F17: n | G17: n | H17: PUBLIC
A18: OrgUnit | B18: n | C18: RELATION | D18: rppublications | E18: OrgUnit's Researchers publications | F18: n | G18: n | H18: PUBLIC
A19: OrgUnit | B19: n | C19: RELATION | D19: people | E19: OrgUnit's Researchers | F19: n | G19: n | H19: PUBLIC
A20: OrgUnit | B20: n | C20: RELATION | D20: projects | E20: OrgUnit funded Projects | F20: n | G20: n | H20: PUBLIC
A21: OrgUnit | B21: n | D21: heading | F21: n | G21: n | H21: PUBLIC
A22: OrgUnit | B22: n | D22: description | E22: Description | F22: n | G22: n | H22: PUBLIC
A23: OrgUnit | B23: n | C23: RELATION | D23: organizations | E23: SubOrgUnits | F23: n | G23: n | H23: PUBLIC
A24: OrgUnit | B24: n | D24: details | E24: Details | F24: n | G24: n | H24: PUBLIC
A25: OrgUnit | B25: n | D25: orgcard | E25: Card | F25: n | G25: y | H25: PUBLIC
A26: OrgUnit | B26: n | C26: METRICS | D26: metrics | E26: Metrics | F26: n | G26: n | H26: PUBLIC
A27: Project | B27: n | D27: description | E27: Description | F27: n | G27: n | H27: PUBLIC
A28: Project | B28: n | C28: RELATION | D28: researchoutputs | E28: Research Outputs | F28: n | G28: n | H28: PUBLIC
A29: Project | B29: n | C29: RELATION | D29: fundings | E29: Fundings | F29: n | G29: n | H29: PUBLIC
A30: Project | B30: n | D30: primarydata | E30: Primary Data | F30: n | G30: n | H30: PUBLIC
A31: Project | B31: n | D31: details | E31: Details | F31: n | G31: n | H31: PUBLIC
A32: Project | B32: n | D32: projectcard | E32: Project Card | F32: n | G32: n | H32: PUBLIC
A33: Project | B33: n | C33: METRICS | D33: metrics | E33: Metrics | F33: n | G33: n | H33: PUBLIC
A34: Funding | B34: n | D34: primarydata | E34: Primary Data | F34: n | G34: n | H34: PUBLIC
A35: Funding | B35: n | C35: RELATION | D35: researchoutputs | E35: Research Outputs | F35: n | G35: n | H35: PUBLIC
A36: Funding | B36: n | D36: financialdata | E36: Financial Data | F36: n | G36: n | H36: CUSTOM DATA
A37: Funding | B37: n | C37: METRICS | D37: metrics | E37: Metrics | F37: n | G37: n | H37: PUBLIC
A38: Journal | B38: n | D38: details | E38: Journal description | F38: n | G38: n | H38: PUBLIC
A39: Journal | B39: n | C39: METRICS | D39: metrics | E39: Metrics | F39: n | G39: n | H39: PUBLIC
A40: Event | B40: n | D40: details | E40: Description | F40: n | G40: n | H40: PUBLIC
...

Sheet box2metadata
A1: ENTITY | B1: BOX | C1: ROW | D1: CELL | E1: FIELDTYPE | F1: METADATA | G1: VALUE | H1: BUNDLE | I1: LABEL | J1: LABEL_AS_HEADING | K1: RENDERING | L1: VALUES_INLINE | M1: ROW_STYLE | N1: CELL_STYLE | O1: STYLE_LABEL | P1: STYLE_VALUE
A2: OrgUnit | B2: description | C2: 1 | D2: 1 | E2: METADATA | F2: organization.address.addressCountry | I2: Country | J2: n | L2: n | O2: font-weight-bold col-3
A3: OrgUnit | B3: description | C3: 2 | D3: 1 | E3: METADATA | F3: organization.address.addressLocality | I3: City | J3: n | L3: n | O3: font-weight-bold col-3
A4: OrgUnit | B4: description | C4: 3 | D4: 1 | E4: METADATA | F4: dc.description.abstract | I4: Description | J4: n | K4: longtext | L4: n | O4: font-weight-bold col-3
A5: OrgUnit | B5: heading | C5: 1 | D5: 1 | E5: METADATA | F5: dc.title | J5: n | K5: heading | L5: n | N5: px-2 | O5: font-weight-bold col-3
A6: OrgUnit | B6: details | C6: 1 | D6: 1 | E6: BITSTREAM | F6: dc.type | G6: logo | H6: ORIGINAL | J6: n | K6: thumbnail | L6: n | N6: col-3
A7: OrgUnit | B7: details | C7: 1 | D7: 2 | E7: METADATA | F7: crisou.director | I7: Director | J7: n | K7: crisref | L7: n | O7: font-weight-bold col-3
A8: OrgUnit | B8: details | C8: 1 | D8: 2 | E8: METADATA | F8: organization.parentOrganization | I8: Parent Organisation | J8: n | K8: crisref | L8: n | O8: font-weight-bold col-3
A9: OrgUnit | B9: details | C9: 1 | D9: 2 | E9: METADATA | F9: organization.foundingDate | I9: Founding Date | J9: n | K9: date | L9: n | O9: font-weight-bold col-3
A10: OrgUnit | B10: details | C10: 1 | D10: 2 | E10: METADATA | F10: crisou.boards | I10: Boards | J10: n | K10: crisref | L10: n | O10: font-weight-bold col-3
A11: OrgUnit | B11: orgcard | C11: 1 | D11: 1 | E11: BITSTREAM | F11: dc.type | G11: logo | H11: ORIGINAL | J11: n | K11: thumbnail | L11: n | N11: col-3
A12: OrgUnit | B12: orgcard | C12: 1 | D12: 2 | E12: METADATA | F12: dc.title | I12: Organisation Name | J12: n | L12: n | N12: px-2 | O12: font-weight-bold col-3
A13: OrgUnit | B13: orgcard | C13: 1 | D13: 2 | E13: METADATA | F13: crisou.director | I13: Director | J13: n | K13: crisref | L13: n | O13: font-weight-bold col-3
A14: OrgUnit | B14: orgcard | C14: 1 | D14: 2 | E14: METADATA | F14: organization.parentOrganization | I14: Parent Organisation | J14: n | K14: crisref | L14: n | O14: font-weight-bold col-3
A15: OrgUnit | B15: orgcard | C15: 1 | D15: 2 | E15: METADATA | F15: organization.foundingDate | I15: Founding Date | J15: n | K15: date | L15: n | O15: font-weight-bold col-3
A16: OrgUnit | B16: orgcard | C16: 1 | D16: 2 | E16: METADATA | F16: organization.address.addressLocality | I16: City | J16: n | L16: n | O16: font-weight-bold col-3
A17: OrgUnit | B17: orgcard | C17: 1 | D17: 2 | E17: METADATA | F17: organization.address.addressCountry | I17: Country | J17: n | L17: n | O17: font-weight-bold col-3
A18: Project | B18: description | C18: 2 | D18: 1 | E18: METADATA | F18: dc.description.abstract | I18: Description | J18: n | K18: longtext | L18: n | O18: font-weight-bold col-3
A19: Project | B19: description | C19: 1 | D19: 1 | E19: METADATA | F19: dc.subject | I19: Keywords | J19: n | K19: tag | L19: n | O19: font-weight-bold col-3
A20: Project | B20: primarydata | C20: 1 | D20: 1 | E20: BITSTREAM | F20: dc.type | G20: logo | H20: ORIGINAL | J20: n | K20: thumbnail | L20: n | N20: col-3
A21: Project | B21: primarydata | C21: 1 | D21: 2 | E21: METADATA | F21: oairecerif.acronym | I21: Acronym | J21: n | L21: n | N21: px-2 | O21: font-weight-bold col-3
A22: Project | B22: primarydata | C22: 1 | D22: 2 | E22: METADATA | F22: dc.title | I22: Project Title | J22: n | L22: n | O22: font-weight-bold col-3
A23: Project | B23: primarydata | C23: 1 | D23: 2 | E23: METADATA | F23: crispj.coordinator | I23: Consortium Coordinator | J23: n | K23: crisref | L23: n | O23: font-weight-bold col-3
A24: Project | B24: primarydata | C24: 1 | D24: 2 | E24: METADATA | F24: crispj.partnerou | I24: Partner Organisations | J24: n | K24: crisref | L24: n | O24: font-weight-bold col-3
A25: Project | B25: primarydata | C25: 1 | D25: 2 | E25: METADATA | F25: oairecerif.internalid | I25: Internal ID | J25: n | L25: n | O25: font-weight-bold col-3
A26: Project | B26: primarydata | C26: 1 | D26: 2 | E26: METADATA | F26: oairecerif.project.status | I26: Status | J26: n | L26: n | O26: font-weight-bold col-3
A27: Project | B27: primarydata | C27: 2 | D27: 1 | E27: METADATA | F27: oairecerif.project.startDate | I27: Start Date | J27: n | K27: date | L27: n | O27: font-weight-bold col-4
A28: Project | B28: primarydata | C28: 2 | D28: 2 | E28: METADATA | F28: oairecerif.project.endDate | I28: End Date | J28: n | K28: date | L28: n | O28: font-weight-bold col-4
A29: Project | B29: details | C29: 1 | D29: 1 | E29: METADATA | F29: crispj.investigator | I29: Principal Investigator | J29: n | K29: crisref | L29: n | O29: font-weight-bold col-3
A30: Project | B30: details | C30: 2 | D30: 1 | E30: METADATA | F30: crispj.coinvestigators | I30: Investigators | J30: n | K30: crisref | L30: n | O30: font-weight-bold col-3
A31: Project | B31: details | C31: 3 | D31: 1 | E31: METADATA | F31: crispj.organization | I31: Organisations | J31: n | K31: crisref | L31: n | O31: font-weight-bold col-3
A32: Project | B32: details | C32: 4 | D32: 1 | E32: METADATA | F32: dc.relation.equipment | I32: Uses | J32: n | K32: crisref | L32: n | O32: font-weight-bold col-3
A33: Project | B33: details | C33: 5 | D33: 1 | E33: METADATA | F33: oairecerif.identifier.url | I33: Project Web Site | J33: n | K33: link | L33: n | O33: font-weight-bold col-3
A34: Project | B34: details | C34: 6 | D34: 1 | E34: METADATA | F34: crispj.openaireid | I34: OpenAIRE ID | J34: n | L34: n | O34: font-weight-bold col-3
A35: Project | B35: projectcard | C35: 1 | D35: 1 | E35: BITSTREAM | F35: dc.type | G35: logo | H35: ORIGINAL | J35: n | K35: thumbnail | L35: n | N35: col-3
A36: Project | B36: projectcard | C36: 1 | D36: 2 | E36: METADATA | F36: dc.title | I36: Project Title | J36: n | L36: n | N36: px-2 | O36: font-weight-bold col-3
A37: Project | B37: projectcard | C37: 1 | D37: 2 | E37: METADATA | F37: oairecerif.internalid | I37: Internal ID | J37: n | L37: n | O37: font-weight-bold col-3
A38: Project | B38: projectcard | C38: 1 | D38: 2 | E38: METADATA | F38: oairecerif.project.status | I38: Status | J38: n | L38: n | O38: font-weight-bold col-3
A39: Project | B39: projectcard | C39: 1 | D39: 2 | E39: METADATA | F39: oairecerif.project.startDate | I39: Start Date | J39: n | K39: date | L39: n | O39: font-weight-bold col-3
A40: Project | B40: projectcard | C40: 1 | D40: 2 | E40: METADATA | F40: oairecerif.project.endDate | I40: End Date | J40: n | K40: date | L40: n | O40: font-weight-bold col-3
...

Sheet metadatagroups
A1: ENTITY | B1: PARENT | C1: FIELDTYPE | D1: METADATA | E1: VALUE | F1: BUNDLE | G1: LABEL | H1: RENDERING | I1: STYLE_LABEL | J1: STYLE_VALUE
A2: Person | B2: crisrp.qualification | C2: METADATA | D2: crisrp.qualification | G2: Title | H2: text | I2: font-weight-bold
A3: Person | B3: crisrp.qualification | C3: METADATA | D3: crisrp.qualification.start | G3: Start | H3: date | I3: font-weight-bold
A4: Person | B4: crisrp.qualification | C4: METADATA | D4: crisrp.qualification.end | G4: End | H4: date | I4: font-weight-bold
A5: Person | B5: oairecerif.person.affiliation | C5: METADATA | D5: oairecerif.affiliation.role | G5: Role | H5: text | I5: font-weight-bold
A6: Person | B6: oairecerif.person.affiliation | C6: METADATA | D6: oairecerif.person.affiliation | G6: Organisation | H6: crisref | I6: font-weight-bold
A7: Person | B7: oairecerif.person.affiliation | C7: METADATA | D7: oairecerif.affiliation.startDate | G7: Start | H7: date | I7: font-weight-bold
A8: Person | B8: oairecerif.person.affiliation | C8: METADATA | D8: oairecerif.affiliation.endDate | G8: End | H8: date | I8: font-weight-bold
A9: Person | B9: crisrp.education | C9: METADATA | D9: crisrp.education.role | G9: Role | H9: text | I9: font-weight-bold
A10: Person | B10: crisrp.education | C10: METADATA | D10: crisrp.education | G10: Organisation | H10: crisref | I10: font-weight-bold
A11: Person | B11: crisrp.education | C11: METADATA | D11: crisrp.education.start | G11: Start | H11: date | I11: font-weight-bold
A12: Person | B12: crisrp.education | C12: METADATA | D12: crisrp.education.end | G12: End | H12: date | I12: font-weight-bold
A13: Publication | B13: dc.contributor.author | C13: METADATA | D13: dc.contributor.author | G13: Author | H13: crisref | I13: font-weight-bold
... A18: Product | B18: dc.contributor.author | C18: METADATA | D18: oairecerif.author.affiliation | G18: Affiliation | H18: crisref | I18: font-weight-bold
A19: Product | B19: dc.relation.publication | C19: METADATA | D19: dc.relation.publication | H19: crisref | I19: font-weight-bold
A20: Product | B20: dc.relation.publication | C20: METADATA | D20: dc.relation.doi | H20: identifier.doi | I20: font-weight-bold | J20: text-nowrap
A21: Patent | B21: dc.contributor.author | C21: METADATA | D21: dc.contributor.author | G21: Inventor | H21: crisref | I21: font-weight-bold
A22: Patent | B22: dc.contributor.author | C22: METADATA | D22: oairecerif.author.affiliation | G22: Affiliation | H22: crisref | I22: font-weight-bold

Sheet box2metrics
A1: ENTITY | B1: BOX | C1: METRIC_TYPE
A2: Publication | B2: metrics | C2: scopusCitation, wosCitation
A3: Publication | B3: altmetrics | C3: altmetric, dimensions
A4: Publication | B4: usagemetrics | C4: view, download, google-scholar, embedded-view, embedded-download
A5: Patent | B5: metrics | C5: scopusCitation, wosCitation
A6: Patent | B6: altmetrics | C6: altmetric, dimensions
A7: Patent | B7: usagemetrics | C7: view, download, embedded-view, embedded-download
A8: Product | B8: metrics | C8: scopusCitation, wosCitation
A9: Product | B9: altmetrics | C9: altmetric, dimensions
A10: Product | B10: usagemetrics | C10: view, download, embedded-view, embedded-download
A11: Person | B11: metrics | C11: scopus-author-h-index, scopus-author-coauthor-count, scopus-author-cited-count, scopus-author-citation-count, scopus-author-document-count, wosPersonCitation
A12: Person | B12: usagemetrics | C12: view, embedded-view, google-scholar
... A18: Funding | B18: metrics | C18: view, embedded-view

Sheet box2hierarchicalvocabulary
A1: ENTITY | B1: BOX | C1: VOCABULARY | D1: METADATA
A2: Publication | B2: hierarchy | C2: publication-coar-types | D2: dc.type
A3: Person | B3: affiliation | C3: orgunits | D3: person.affiliation.name

Sheet tabpolicy
A1: ENTITY | B1: SHORTNAME | C1: METADATA | D1: GROUP
A2: Person | B2: secure | C2: cris.policy.group

Sheet boxpolicy
A1: ENTITY | B1: SHORTNAME | C1: METADATA | D1: GROUP
A2: Person | B2: secure | C2: cris.policy.eperson
A3: Funding | B3: financialdata | C3: crisfund.investigators
A4: Funding | B4: financialdata | C4: crisfund.coinvestigators

Sheet utilsdata
A1: BOX-TYPES | B1: METADATA-RENDERING | C1: Security
A2: RELATION | B2: heading | C2: PUBLIC
A3: METADATA | B3: text | C3: ADMINISTRATOR
A4: METRICS | B4: longtext | C4: OWNER ONLY
A5: ORCID_SYNC_SETTINGS | B5: link | C5: OWNER & ADMINISTRATOR
A6: ORCID_AUTHORIZATIONS | B6: link.label | C6: CUSTOM DATA
A7: ORCID_SYNC_QUEUE | B7: date | C7: CUSTOM DATA & ADMINISTRATOR
B8: identifier
B9: crisref
B10: thumbnail
B11: attachment
B12: tag

Sheet tab_i18n
A1: PREFIX | B1: AUTOGENERATED I18N keys
A2: layout.tab.header. | B2: =IF(OR(ISBLANK(tab!$C2),EXACT(MID(tab!$C2,1,LEN($A$2)),$A$2)),"",""""&$A$2&tab!$A2&"."&tab!$B2&""": """&tab!$C2&""",") -> "layout.tab.header.Person.details": "Profile",
B3: =IF(OR(ISBLANK(tab!$C3),EXACT(MID(tab!$C3,1,LEN($A$2)),$A$2)),"",""""&$A$2&tab!$A3&"."&tab!$B3&""": """&tab!$C3&""",") -> "layout.tab.header.Person.creators": "creator of",
B4: =IF(OR(ISBLANK(tab!#REF!),EXACT(MID(tab!#REF!,1,LEN($A$2)),$A$2)),"",""""&$A$2&tab!#REF!&"."&tab!#REF!&""": """&tab!#REF!&""",") -> #REF!
B5: =IF(OR(ISBLANK(tab!#REF!),EXACT(MID(tab!#REF!,1,LEN($A$2)),$A$2)),"",""""&$A$2&tab!#REF!&"."&tab!#REF!&""": """&tab!#REF!&""",") -> #REF!
B6: =IF(OR(ISBLANK(tab!#REF!),EXACT(MID(tab!#REF!,1,LEN($A$2)),$A$2)),"",""""&$A$2&tab!#REF!&"."&tab!#REF!&""": """&tab!#REF!&""",") -> #REF!
B7: =IF(OR(ISBLANK(tab!#REF!),EXACT(MID(tab!#REF!,1,LEN($A$2)),$A$2)),"",""""&$A$2&tab!#REF!&"."&tab!#REF!&""": """&tab!#REF!&""",") -> #REF!
B8: =IF(OR(ISBLANK(tab!#REF!),EXACT(MID(tab!#REF!,1,LEN($A$2)),$A$2)),"",""""&$A$2&tab!#REF!&"."&tab!#REF!&""": """&tab!#REF!&""",") -> #REF!
B9: =IF(OR(ISBLANK(tab!$C8),EXACT(MID(tab!$C8,1,LEN($A$2)),$A$2)),"",""""&$A$2&tab!$A8&"."&tab!$B8&""": """&tab!$C8&""",") -> "layout.tab.header.OrgUnit.maininformation": "Information",
B10: =IF(OR(ISBLANK(tab!#REF!),EXACT(MID(tab!#REF!,1,LEN($A$2)),$A$2)),"",""""&$A$2&tab!#REF!&"."&tab!#REF!&""": """&tab!#REF!&""",") -> #REF!
B11: =IF(OR(ISBLANK(tab!#REF!),EXACT(MID(tab!#REF!,1,LEN($A$2)),$A$2)),"",""""&$A$2&tab!#REF!&"."&tab!#REF!&""": """&tab!#REF!&""",") -> #REF!
B12: =IF(OR(ISBLANK(tab!$C9),EXACT(MID(tab!$C9,1,LEN($A$2)),$A$2)),"",""""&$A$2&tab!$A9&"."&tab!$B9&""": """&tab!$C9&""",") -> "layout.tab.header.OrgUnit.publications": "Publications",
B13: =IF(OR(ISBLANK(tab!#REF!),EXACT(MID(tab!#REF!,1,LEN($A$2)),$A$2)),"",""""&$A$2&tab!#REF!&"."&tab!#REF!&""": """&tab!#REF!&""",") -> #REF!
B14: =IF(OR(ISBLANK(tab!$C10),EXACT(MID(tab!$C10,1,LEN($A$2)),$A$2)),"",""""&$A$2&tab!$A10&"."&tab!$B10&""": """&tab!$C10&""",") -> "layout.tab.header.OrgUnit.projects": "Projects",
B15: =IF(OR(ISBLANK(tab!#REF!),EXACT(MID(tab!#REF!,1,LEN($A$2)),$A$2)),"",""""&$A$2&tab!#REF!&"."&tab!#REF!&""": """&tab!#REF!&""",") -> #REF!
B16: =IF(OR(ISBLANK(tab!$C11),EXACT(MID(tab!$C11,1,LEN($A$2)),$A$2)),"",""""&$A$2&tab!$A11&"."&tab!$B11&""": """&tab!$C11&""",") -> "layout.tab.header.OrgUnit.people": "People",
B17: =IF(OR(ISBLANK(tab!$C13),EXACT(MID(tab!$C13,1,LEN($A$2)),$A$2)),"",""""&$A$2&tab!$A13&"."&tab!$B13&""": """&tab!$C13&""",") -> "layout.tab.header.Project.maininformation": "Information",
B18: =IF(OR(ISBLANK(tab!#REF!),EXACT(MID(tab!#REF!,1,LEN($A$2)),$A$2)),"",""""&$A$2&tab!#REF!&"."&tab!#REF!&""": """&tab!#REF!&""",") -> #REF!
B19: =IF(OR(ISBLANK(tab!#REF!),EXACT(MID(tab!#REF!,1,LEN($A$2)),$A$2)),"",""""&$A$2&tab!#REF!&"."&tab!#REF!&""": """&tab!#REF!&""",") -> #REF!
B20: =IF(OR(ISBLANK(tab!#REF!),EXACT(MID(tab!#REF!,1,LEN($A$2)),$A$2)),"",""""&$A$2&tab!#REF!&"."&tab!#REF!&""": """&tab!#REF!&""",") -> #REF!
B21: =IF(OR(ISBLANK(tab!#REF!),EXACT(MID(tab!#REF!,1,LEN($A$2)),$A$2)),"",""""&$A$2&tab!#REF!&"."&tab!#REF!&""": """&tab!#REF!&""",") -> #REF!
B22: =IF(OR(ISBLANK(tab!$C14),EXACT(MID(tab!$C14,1,LEN($A$2)),$A$2)),"",""""&$A$2&tab!$A14&"."&tab!$B14&""": """&tab!$C14&""",") -> "layout.tab.header.Event.details": "Details",
B23: =IF(OR(ISBLANK(tab!#REF!),EXACT(MID(tab!#REF!,1,LEN($A$2)),$A$2)),"",""""&$A$2&tab!#REF!&"."&tab!#REF!&""": """&tab!#REF!&""",") -> #REF!
B24: =IF(OR(ISBLANK(tab!#REF!),EXACT(MID(tab!#REF!,1,LEN($A$2)),$A$2)),"",""""&$A$2&tab!#REF!&"."&tab!#REF!&""": """&tab!#REF!&""",") -> #REF!
B25: =IF(OR(ISBLANK(tab!#REF!),EXACT(MID(tab!#REF!,1,LEN($A$2)),$A$2)),"",""""&$A$2&tab!#REF!&"."&tab!#REF!&""": """&tab!#REF!&""",") -> #REF!
B26: =IF(OR(ISBLANK(tab!#REF!),EXACT(MID(tab!#REF!,1,LEN($A$2)),$A$2)),"",""""&$A$2&tab!#REF!&"."&tab!#REF!&""": """&tab!#REF!&""",") -> #REF!
B27: =IF(OR(ISBLANK(tab!$C18),EXACT(MID(tab!$C18,1,LEN($A$2)),$A$2)),"",""""&$A$2&tab!$A18&"."&tab!$B18&""": """&tab!$C18&""",") -> "layout.tab.header.Publication.details": "Details",
B28: =IF(OR(ISBLANK(tab!#REF!),EXACT(MID(tab!#REF!,1,LEN($A$2)),$A$2)),"",""""&$A$2&tab!#REF!&"."&tab!#REF!&""": """&tab!#REF!&""",") -> #REF!
B29: =IF(OR(ISBLANK(tab!#REF!),EXACT(MID(tab!#REF!,1,LEN($A$2)),$A$2)),"",""""&$A$2&tab!#REF!&"."&tab!#REF!&""": """&tab!#REF!&""",") -> #REF!
B30: =IF(OR(ISBLANK(tab!#REF!),EXACT(MID(tab!#REF!,1,LEN($A$2)),$A$2)),"",""""&$A$2&tab!#REF!&"."&tab!#REF!&""": """&tab!#REF!&""",") -> #REF!
B31: =IF(OR(ISBLANK(tab!#REF!),EXACT(MID(tab!#REF!,1,LEN($A$2)),$A$2)),"",""""&$A$2&tab!#REF!&"."&tab!#REF!&""": """&tab!#REF!&""",") -> #REF!
B32: =IF(OR(ISBLANK(tab!#REF!),EXACT(MID(tab!#REF!,1,LEN($A$2)),$A$2)),"",""""&$A$2&tab!#REF!&"."&tab!#REF!&""": """&tab!#REF!&""",") -> #REF!
B33: =IF(OR(ISBLANK(tab!$C19),EXACT(MID(tab!$C19,1,LEN($A$2)),$A$2)),"",""""&$A$2&tab!$A19&"."&tab!$B19&""": """&tab!$C19&""",") -> "layout.tab.header.Fond.details": "Fond Details",
B34: =IF(OR(ISBLANK(tab!$C20),EXACT(MID(tab!$C20,1,LEN($A$2)),$A$2)),"",""""&$A$2&tab!$A20&"."&tab!$B20&""": """&tab!$C20&""",") -> "layout.tab.header.Fond.fondcontext": "Fond Context",
B35: =IF(OR(ISBLANK(tab!$C21),EXACT(MID(tab!$C21,1,LEN($A$2)),$A$2)),"",""""&$A$2&tab!$A21&"."&tab!$B21&""": """&tab!$C21&""",") -> "layout.tab.header.Fond.fondevents": "Fond Events",
B36: =IF(OR(ISBLANK(tab!$C22),EXACT(MID(tab!$C22,1,LEN($A$2)),$A$2)),"",""""&$A$2&tab!$A22&"."&tab!$B22&""": """&tab!$C22&""",") -> "layout.tab.header.Fond.fondeditors": "FondEditors",
B37: =IF(OR(ISBLANK(tab!$C23),EXACT(MID(tab!$C23,1,LEN($A$2)),$A$2)),"",""""&$A$2&tab!$A23&"."&tab!$B23&""": """&tab!$C23&""",") -> "layout.tab.header.Place.details": "Place Details",
B38: =IF(OR(ISBLANK(tab!$C24),EXACT(MID(tab!$C24,1,LEN($A$2)),$A$2)),"",""""&$A$2&tab!$A24&"."&tab!$B24&""": """&tab!$C24&""",") -> "layout.tab.header.Place.placeevents": "Place Events",
B39: =IF(OR(ISBLANK(tab!$C25),EXACT(MID(tab!$C25,1,LEN($A$2)),$A$2)),"",""""&$A$2&tab!$A25&"."&tab!$B25&""": """&tab!$C25&""",") -> "layout.tab.header.Place.placeexternallinks": "External Links",
B40: =IF(OR(ISBLANK(tab!$C26),EXACT(MID(tab!$C26,1,LEN($A$2)),$A$2)),"",""""&$A$2&tab!$A26&"."&tab!$B26&""": """&tab!$C26&""",") -> "layout.tab.header.Family.details": "Family details",
...

Sheet box_i18n
A1: PREFIX | B1: AUTOGENERATED I18N keys
A2: layout.box.header. | B2: =IF(OR(ISBLANK(box!$E2),EXACT(MID(box!$E2,1,LEN($A$2)),$A$2)),"",""""&$A$2&box!$A2&"."&box!$D2&""": """&box!$E2&""",")
B3: =IF(OR(ISBLANK(box!$E3),EXACT(MID(box!$E3,1,LEN($A$2)),$A$2)),"",""""&$A$2&box!$A3&"."&box!$D3&""": """&box!$E3&""",") -> "layout.box.header.Person.projects": "Projects",
B4: =IF(OR(ISBLANK(box!$E4),EXACT(MID(box!$E4,1,LEN($A$2)),$A$2)),"",""""&$A$2&box!$A4&"."&box!$D4&""": """&box!$E4&""",") -> "layout.box.header.Person.researchoutputs": "Publications",
B5: =IF(OR(ISBLANK(box!$E5),EXACT(MID(box!$E5,1,LEN($A$2)),$A$2)),"",""""&$A$2&box!$A5&"."&box!$D5&""": """&box!$E5&""",") -> "layout.box.header.Person.qualifications": "Professional Qualifications",
B6: =IF(OR(ISBLANK(box!$E6),EXACT(MID(box!$E6,1,LEN($A$2)),$A$2)),"",""""&$A$2&box!$A6&"."&box!$D6&""": """&box!$E6&""",") -> "layout.box.header.Person.media": "Media Contact Directory",
B7: =IF(OR(ISBLANK(box!$E7),EXACT(MID(box!$E7,1,LEN($A$2)),$A$2)),"",""""&$A$2&box!$A7&"."&box!$D7&""": """&box!$E7&""",") -> "layout.box.header.Person.orcidsyncqueue": "ORCID Registry Queue",
B8: =IF(OR(ISBLANK(box!$E8),EXACT(MID(box!$E8,1,LEN($A$2)),$A$2)),"",""""&$A$2&box!$A8&"."&box!$D8&""": """&box!$E8&""",") -> "layout.box.header.Person.namecard": "Name Card",
B9: =IF(OR(ISBLANK(box!$E9),EXACT(MID(box!$E9,1,LEN($A$2)),$A$2)),"",""""&$A$2&box!$A9&"."&box!$D9&""": """&box!$E9&""",") -> "layout.box.header.Person.orcidsyncsettings": "ORCID Synchronization settings",
B10: =IF(OR(ISBLANK(box!$E10),EXACT(MID(box!$E10,1,LEN($A$2)),$A$2)),"",""""&$A$2&box!$A10&"."&box!$D10&""": """&box!$E10&""",") -> "layout.box.header.Person.researcherprofile": "Profile",
B11: =IF(OR(ISBLANK(box!$E11),EXACT(MID(box!$E11,1,LEN($A$2)),$A$2)),"",""""&$A$2&box!$A11&"."&box!$D11&""": """&box!$E11&""",") -> "layout.box.header.Person.orcidauthorizations": "ORCID Authorizations",
B12: =IF(OR(ISBLANK(box!$E12),EXACT(MID(box!$E12,1,LEN($A$2)),$A$2)),"",""""&$A$2&box!$A12&"."&box!$D12&""": """&box!$E12&""",") -> "layout.box.header.Person.metrics": "Metrics",
B13: =IF(OR(ISBLANK(box!$E13),EXACT(MID(box!$E13,1,LEN($A$2)),$A$2)),"",""""&$A$2&box!$A13&"."&box!$D13&""": """&box!$E13&""",") -> "layout.box.header.Person.usagemetrics": "Usage Metrics",
B14: =IF(OR(ISBLANK(box!$E14),EXACT(MID(box!$E14,1,LEN($A$2)),$A$2)),"",""""&$A$2&box!$A14&"."&box!$D14&""": """&box!$E14&""",") -> "layout.box.header.Person.secure": "Secured box",
B15: =IF(OR(ISBLANK(box!$E16),EXACT(MID(box!$E16,1,LEN($A$2)),$A$2)),"",""""&$A$2&box!$A16&"."&box!$D16&""": """&box!$E16&""",") -> "layout.box.header.OrgUnit.rpprojects": "OrgUnit's Researchers projects",
B16: =IF(OR(ISBLANK(box!$E17),EXACT(MID(box!$E17,1,LEN($A$2)),$A$2)),"",""""&$A$2&box!$A17&"."&box!$D17&""": """&box!$E17&""",") -> "layout.box.header.OrgUnit.publications": "OrgUnit's Publications",
B17: =IF(OR(ISBLANK(box!$E18),EXACT(MID(box!$E18,1,LEN($A$2)),$A$2)),"",""""&$A$2&box!$A18&"."&box!$D18&""": """&box!$E18&""",") -> "layout.box.header.OrgUnit.rppublications": "OrgUnit's Researchers publications",
B18: =IF(OR(ISBLANK(box!$E19),EXACT(MID(box!$E19,1,LEN($A$2)),$A$2)),"",""""&$A$2&box!$A19&"."&box!$D19&""": """&box!$E19&""",") -> "layout.box.header.OrgUnit.people": "OrgUnit's Researchers",
B19: =IF(OR(ISBLANK(box!$E20),EXACT(MID(box!$E20,1,LEN($A$2)),$A$2)),"",""""&$A$2&box!$A20&"."&box!$D20&""": """&box!$E20&""",") -> "layout.box.header.OrgUnit.projects": "OrgUnit funded Projects",
B20: =IF(OR(ISBLANK(box!$E21),EXACT(MID(box!$E21,1,LEN($A$2)),$A$2)),"",""""&$A$2&box!$A21&"."&box!$D21&""": """&box!$E21&""",")
B21: =IF(OR(ISBLANK(box!$E22),EXACT(MID(box!$E22,1,LEN($A$2)),$A$2)),"",""""&$A$2&box!$A22&"."&box!$D22&""": """&box!$E22&""",") -> "layout.box.header.OrgUnit.description": "Description",
B22: =IF(OR(ISBLANK(box!$E23),EXACT(MID(box!$E23,1,LEN($A$2)),$A$2)),"",""""&$A$2&box!$A23&"."&box!$D23&""": """&box!$E23&""",") -> "layout.box.header.OrgUnit.organizations": "SubOrgUnits",
B23: =IF(OR(ISBLANK(box!$E24),EXACT(MID(box!$E24,1,LEN($A$2)),$A$2)),"",""""&$A$2&box!$A24&"."&box!$D24&""": """&box!$E24&""",") -> "layout.box.header.OrgUnit.details": "Details",
B24: =IF(OR(ISBLANK(box!$E25),EXACT(MID(box!$E25,1,LEN($A$2)),$A$2)),"",""""&$A$2&box!$A25&"."&box!$D25&""": """&box!$E25&""",") -> "layout.box.header.OrgUnit.orgcard": "Card",
B25: =IF(OR(ISBLANK(box!$E26),EXACT(MID(box!$E26,1,LEN($A$2)),$A$2)),"",""""&$A$2&box!$A26&"."&box!$D26&""": """&box!$E26&""",") -> "layout.box.header.OrgUnit.metrics": "Metrics",
B26: =IF(OR(ISBLANK(box!$E27),EXACT(MID(box!$E27,1,LEN($A$2)),$A$2)),"",""""&$A$2&box!$A27&"."&box!$D27&""": """&box!$E27&""",") -> "layout.box.header.Project.description": "Description",
... B47: =IF(OR(ISBLANK(box!$E48),EXACT(MID(box!$E48,1,LEN($A$2)),$A$2)),"",""""&$A$2&box!$A48&"."&box!$D48&""": """&box!$E48&""",") -> "layout.box.header.Publication.usagemetrics": "Usage Metrics",
B48: =IF(OR(ISBLANK(box!$E50),EXACT(MID(box!$E50,1,LEN($A$2)),$A$2)),"",""""&$A$2&box!$A50&"."&box!$D50&""": """&box!$E50&""",") -> "layout.box.header.Patent.details": "Details",
B49: =IF(OR(ISBLANK(box!$E51),EXACT(MID(box!$E51,1,LEN($A$2)),$A$2)),"",""""&$A$2&box!$A51&"."&box!$D51&""": """&box!$E51&""",") -> "layout.box.header.Patent.metrics": "Metrics",
B50: =IF(OR(ISBLANK(box!$E52),EXACT(MID(box!$E52,1,LEN($A$2)),$A$2)),"",""""&$A$2&box!$A52&"."&box!$D52&""": """&box!$E52&""",") -> "layout.box.header.Patent.altmetrics": "Metrics",
B51: =IF(OR(ISBLANK(box!$E53),EXACT(MID(box!$E53,1,LEN($A$2)),$A$2)),"",""""&$A$2&box!$A53&"."&box!$D53&""": """&box!$E53&""",") -> "layout.box.header.Patent.usagemetrics": "Metrics",
B52: =IF(OR(ISBLANK(box!$E54),EXACT(MID(box!$E54,1,LEN($A$2)),$A$2)),"",""""&$A$2&box!$A54&"."&box!$D54&""": """&box!$E54&""",") -> "layout.box.header.Product.details": "Details",
B53: =IF(OR(ISBLANK(box!$E55),EXACT(MID(box!$E55,1,LEN($A$2)),$A$2)),"",""""&$A$2&box!$A55&"."&box!$D55&""": """&box!$E55&""",") -> "layout.box.header.Product.metrics": "Metrics",
B54: =IF(OR(ISBLANK(box!$E56),EXACT(MID(box!$E56,1,LEN($A$2)),$A$2)),"",""""&$A$2&box!$A56&"."&box!$D56&""": """&box!$E56&""",") -> "layout.box.header.Product.altmetrics": "Metrics",
B55: =IF(OR(ISBLANK(box!$E57),EXACT(MID(box!$E57,1,LEN($A$2)),$A$2)),"",""""&$A$2&box!$A57&"."&box!$D57&""": """&box!$E57&""",") -> "layout.box.header.Product.usagemetrics": "Metrics",
B56: =IF(OR(ISBLANK(box!$E58),EXACT(MID(box!$E58,1,LEN($A$2)),$A$2)),"",""""&$A$2&box!$A58&"."&box!$D58&""": """&box!$E58&""",") -> "layout.box.header.Product.mainformation": "Main informations",
B57: =IF(OR(ISBLANK(box!$E59),EXACT(MID(box!$E59,1,LEN($A$2)),$A$2)),"",""""&$A$2&box!$A59&"."&box!$D59&""": """&box!$E59&""",") -> "layout.box.header.Product.references": "References",
B58: =IF(OR(ISBLANK(box!$E60),EXACT(MID(box!$E60,1,LEN($A$2)),$A$2)),"",""""&$A$2&box!$A60&"."&box!$D60&""": """&box!$E60&""",")
B59: =IF(OR(ISBLANK(box!$E61),EXACT(MID(box!$E61,1,LEN($A$2)),$A$2)),"",""""&$A$2&box!$A61&"."&box!$D61&""": """&box!$E61&""",")
... B90: =IF(OR(ISBLANK(box!$E92),EXACT(MID(box!$E92,1,LEN($A$2)),$A$2)),"",""""&$A$2&box!$A92&"."&box!$D92&""": """&box!$E92&""",")

Sheet metadata_i18n
A1: PREFIX | B1: AUTOGENERATED I18N keys
A2: layout.field.label. | B2: =IF(ISBLANK(box2metadata!$I2),"",""""&$A$2&box2metadata!$A2&"."&IF(ISBLANK(box2metadata!$F2),box2metadata!$E2,box2metadata!$F2)&""": """&box2metadata!$I2&""",") -> "layout.field.label.OrgUnit.organization.address.addressCountry": "Country",
B3: =IF(ISBLANK(box2metadata!$I3),"",""""&$A$2&box2metadata!$A3&"."&IF(ISBLANK(box2metadata!$F3),box2metadata!$E3,box2metadata!$F3)&""": """&box2metadata!$I3&""",") -> "layout.field.label.OrgUnit.organization.address.addressLocality": "City",
B4: =IF(ISBLANK(box2metadata!$I4),"",""""&$A$2&box2metadata!$A4&"."&IF(ISBLANK(box2metadata!$F4),box2metadata!$E4,box2metadata!$F4)&""": """&box2metadata!$I4&""",") -> "layout.field.label.OrgUnit.dc.description.abstract": "Description",
B5: =IF(ISBLANK(box2metadata!$I5),"",""""&$A$2&box2metadata!$A5&"."&IF(ISBLANK(box2metadata!$F5),box2metadata!$E5,box2metadata!$F5)&""": """&box2metadata!$I5&""",")
B6: =IF(ISBLANK(box2metadata!$I6),"",""""&$A$2&box2metadata!$A6&"."&IF(ISBLANK(box2metadata!$F6),box2metadata!$E6,box2metadata!$F6)&""": """&box2metadata!$I6&""",")
B7: =IF(ISBLANK(box2metadata!$I7),"",""""&$A$2&box2metadata!$A7&"."&IF(ISBLANK(box2metadata!$F7),box2metadata!$E7,box2metadata!$F7)&""": """&box2metadata!$I7&""",") -> "layout.field.label.OrgUnit.crisou.director": "Director",
B8: =IF(ISBLANK(box2metadata!$I8),"",""""&$A$2&box2metadata!$A8&"."&IF(ISBLANK(box2metadata!$F8),box2metadata!$E8,box2metadata!$F8)&""": """&box2metadata!$I8&""",") -> "layout.field.label.OrgUnit.organization.parentOrganization": "Parent Organisation",
B9: =IF(ISBLANK(box2metadata!$I9),"",""""&$A$2&box2metadata!$A9&"."&IF(ISBLANK(box2metadata!$F9),box2metadata!$E9,box2metadata!$F9)&""": """&box2metadata!$I9&""",") -> "layout.field.label.OrgUnit.organization.foundingDate": "Founding Date",
B10: =IF(ISBLANK(box2metadata!$I10),"",""""&$A$2&box2metadata!$A10&"."&IF(ISBLANK(box2metadata!$F10),box2metadata!$E10,box2metadata!$F10)&""": """&box2metadata!$I10&""",") -> "layout.field.label.OrgUnit.crisou.boards": "Boards",
B11: =IF(ISBLANK(box2metadata!$I11),"",""""&$A$2&box2metadata!$A11&"."&IF(ISBLANK(box2metadata!$F11),box2metadata!$E11,box2metadata!$F11)&""": """&box2metadata!$I11&""",")
B12: =IF(ISBLANK(box2metadata!$I12),"",""""&$A$2&box2metadata!$A12&"."&IF(ISBLANK(box2metadata!$F12),box2metadata!$E12,box2metadata!$F12)&""": """&box2metadata!$I12&""",") -> "layout.field.label.OrgUnit.dc.title": "Organisation Name",
B13: =IF(ISBLANK(box2metadata!$I13),"",""""&$A$2&box2metadata!$A13&"."&IF(ISBLANK(box2metadata!$F13),box2metadata!$E13,box2metadata!$F13)&""": """&box2metadata!$I13&""",") -> "layout.field.label.OrgUnit.crisou.director": "Director",
B14: =IF(ISBLANK(box2metadata!$I14),"",""""&$A$2&box2metadata!$A14&"."&IF(ISBLANK(box2metadata!$F14),box2metadata!$E14,box2metadata!$F14)&""": """&box2metadata!$I14&""",") -> "layout.field.label.OrgUnit.organization.parentOrganization": "Parent Organisation",
... B134: =IF(ISBLANK(box2metadata!$I134),"",""""&$A$2&box2metadata!$A134&"."&IF(ISBLANK(box2metadata!$F134),box2metadata!$E134,box2metadata!$F134)&""": """&box2metadata!$I134&""",") -> "layout.field.label.Patent.BITSTREAM": "File(s)",
B135: =IF(ISBLANK(box2metadata!$I135),"",""""&$A$2&box2metadata!$A135&"."&box2metadata!$F135&""": """&IF(ISBLANK(box2metadata!$I135),box2metadata!$E135,box2metadata!$I135)&""",")
B136: =IF(ISBLANK(box2metadata!$I136),"",""""&$A$2&box2metadata!$A136&"."&box2metadata!$F136&""": """&IF(ISBLANK(box2metadata!$I136),box2metadata!$E136,box2metadata!$I136)&""",")
B137: =IF(ISBLANK(box2metadata!$I137),"",""""&$A$2&box2metadata!$A137&"."&box2metadata!$F137&""": """&IF(ISBLANK(box2metadata!$I137),box2metadata!$E137,box2metadata!$I137)&""",")
B138: =IF(ISBLANK(box2metadata!$I138),"",""""&$A$2&box2metadata!$A138&"."&box2metadata!$F138&""": """&IF(ISBLANK(box2metadata!$I138),box2metadata!$E138,box2metadata!$I138)&""",")
B139: =IF(ISBLANK(box2metadata!$I139),"",""""&$A$2&box2metadata!$A139&"."&box2metadata!$F139&""": """&IF(ISBLANK(box2metadata!$I139),box2metadata!$E139,box2metadata!$I139)&""",")
B140: =IF(ISBLANK(box2metadata!$I140),"",""""&$A$2&box2metadata!$A140&"."&box2metadata!$F140&""": """&IF(ISBLANK(box2metadata!$I140),box2metadata!$E140,box2metadata!$I140)&""",")
B141: =IF(ISBLANK(box2metadata!$I141),"",""""&$A$2&box2metadata!$A141&"."&box2metadata!$F141&""": """&IF(ISBLANK(box2metadata!$I141),box2metadata!$E141,box2metadata!$I141)&""",")
B142: =IF(ISBLANK(box2metadata!$I142),"",""""&$A$2&box2metadata!$A142&"."&box2metadata!$F142&""": """&IF(ISBLANK(box2metadata!$I142),box2metadata!$E142,box2metadata!$I142)&""",")
B143: =IF(ISBLANK(box2metadata!$I143),"",""""&$A$2&box2metadata!$A143&"."&box2metadata!$F143&""": """&IF(ISBLANK(box2metadata!$I143),box2metadata!$E143,box2metadata!$I143)&""",")
B144: =IF(ISBLANK(box2metadata!$I144),"",""""&$A$2&box2metadata!$A144&"."&box2metadata!$F144&""": """&IF(ISBLANK(box2metadata!$I144),box2metadata!$E144,box2metadata!$I144)&""",")
B145: =IF(ISBLANK(box2metadata!$I145),"",""""&$A$2&box2metadata!$A145&"."&box2metadata!$F145&""": """&IF(ISBLANK(box2metadata!$I145),box2metadata!$E145,box2metadata!$I145)&""",")
B146: =IF(ISBLANK(box2metadata!$I146),"",""""&$A$2&box2metadata!$A146&"."&box2metadata!$F146&""": """&IF(ISBLANK(box2metadata!$I146),box2metadata!$E146,box2metadata!$I146)&""",")
... B160: =IF(ISBLANK(box2metadata!$I160),"",""""&$A$2&box2metadata!$A160&"."&box2metadata!$F160&""": """&IF(ISBLANK(box2metadata!$I160),box2metadata!$E160,box2metadata!$I160)&""",")

Sheet metadatagroup_i18n
A1: PREFIX | B1: AUTOGENERATED I18N keys
A2: layout.field.label. | B2: =IF(ISBLANK(metadatagroups!$D2),"",""""&$A$2&metadatagroups!$A2&"."&metadatagroups!$D2&""": """&metadatagroups!$G2&""",") -> "layout.field.label.Person.crisrp.qualification": "Title",
B3: =IF(ISBLANK(metadatagroups!$D3),"",""""&$A$2&metadatagroups!$A3&"."&metadatagroups!$D3&""": """&metadatagroups!$G3&""",") -> "layout.field.label.Person.crisrp.qualification.start": "Start",
B4: =IF(ISBLANK(metadatagroups!$D4),"",""""&$A$2&metadatagroups!$A4&"."&metadatagroups!$D4&""": """&metadatagroups!$G4&""",") -> "layout.field.label.Person.crisrp.qualification.end": "End",
B5: =IF(ISBLANK(metadatagroups!$D5),"",""""&$A$2&metadatagroups!$A5&"."&metadatagroups!$D5&""": """&metadatagroups!$G5&""",") -> "layout.field.label.Person.oairecerif.affiliation.role": "Role",
B6: =IF(ISBLANK(metadatagroups!$D6),"",""""&$A$2&metadatagroups!$A6&"."&metadatagroups!$D6&""": """&metadatagroups!$G6&""",") -> "layout.field.label.Person.oairecerif.person.affiliation": "Organisation",
B7: =IF(ISBLANK(metadatagroups!$D7),"",""""&$A$2&metadatagroups!$A7&"."&metadatagroups!$D7&""": """&metadatagroups!$G7&""",") -> "layout.field.label.Person.oairecerif.affiliation.startDate": "Start",
B8: =IF(ISBLANK(metadatagroups!$D8),"",""""&$A$2&metadatagroups!$A8&"."&metadatagroups!$D8&""": """&metadatagroups!$G8&""",") -> "layout.field.label.Person.oairecerif.affiliation.endDate": "End",
B9: =IF(ISBLANK(metadatagroups!$D9),"",""""&$A$2&metadatagroups!$A9&"."&metadatagroups!$D9&""": """&metadatagroups!$G9&""",") -> "layout.field.label.Person.crisrp.education.role": "Role",
B10: =IF(ISBLANK(metadatagroups!$D10),"",""""&$A$2&metadatagroups!$A10&"."&metadatagroups!$D10&""": """&metadatagroups!$G10&""",") -> "layout.field.label.Person.crisrp.education": "Organisation",
B11: =IF(ISBLANK(metadatagroups!$D11),"",""""&$A$2&metadatagroups!$A11&"."&metadatagroups!$D11&""": """&metadatagroups!$G11&""",") -> "layout.field.label.Person.crisrp.education.start": "Start",
B12: =IF(ISBLANK(metadatagroups!$D12),"",""""&$A$2&metadatagroups!$A12&"."&metadatagroups!$D12&""": """&metadatagroups!$G12&""",") -> "layout.field.label.Person.crisrp.education.end": "End",
B13: =IF(ISBLANK(metadatagroups!$D13),"",""""&$A$2&metadatagroups!$A13&"."&metadatagroups!$D13&""": """&metadatagroups!$G13&""",") -> "layout.field.label.Publication.dc.contributor.author": "Author",
B14: =IF(ISBLANK(metadatagroups!$D14),"",""""&$A$2&metadatagroups!$A14&"."&metadatagroups!$D14&""": """&metadatagroups!$G14&""",") -> "layout.field.label.Publication.oairecerif.author.affiliation": "Affiliation",
... B50: =IF(ISBLANK(metadatagroups!$D50),"",""""&$A$2&metadatagroups!$A50&"."&metadatagroups!$D50&""": """&metadatagroups!$G50&""",")
